Workbook

Sheet README
A1: Professional Portfolio Tracker v3 Fixed
A3: Fixed: Transactions are calculated by Ticker + Level separately.
A4: Fixed: row 4 formulas do not reference the header row.
A5: Only record trades from Strategy Start Date onward.
A6: Use Cash_Flow for future deposits/withdrawals only.
A7: Update Prices manually for current valuation.
A8: Rows prebuilt to 200; copy formulas down if needed.

Sheet Config
A1: Strategy Configuration | D1: Tickers | F1: Levels | H1: Sides
D2: JEPQ | F2: L0+ | H2: BUY
A3: Strategy Start Date | B3: 46037 | D3: QUAL | F3: L1 | H3: SELL
A4: Starting Equity ($) | B4: 99215.41 | D4: SPY | F4: L2
A5: L0+ Target Weight | B5: 0.65 | D5: QQQ
A6: Max L1+L2 Weight | B6: 0.35 | D6: SOXX
A7: Single Ticker Warning | B7: 0.1 | D7: TQQQ

Sheet Prices
A1: Current Prices
A3: Ticker | B3: Last Price | C3: Updated
A4: JEPQ | B4: 59.86 | C4: 46197
A5: QUAL | B5: 213.01 | C5: 46197
A6: SPY | B6: 733.58 | C6: 46197
A7: QQQ | B7: 713.65 | C7: 46197
A8: SOXX | B8: 603.39 | C8: 46197
A9: TQQQ | B9: 74.44 | C9: 46197

Sheet Transactions
A1: Actual Strategy Trades
A3: Date | B3: Ticker | C3: Level | D3: Side | E3: Quantity | F3: Price | G3: Fee | H3: Signed Qty | I3: Gross Value | J3: Cash Impact | K3: Position Before | L3: Cost Basis Before | M3: Avg Cost Before | N3: Realized PnL | O3: Cost Basis After | P3: Position After | Q3: Avg Cost After | R3: Notes | S3: Flag
A4: 46037 | B4: SPY | C4: L1 | D4: Buy | E4: 2.00482 | F4: 574.5 | H4: =IF(OR(D4="",E4=""),"",IF(D4="BUY",E4,-E4)) | I4: =IF(H4="","",ABS(H4)*F4) | J4: =IF(H4="","",-H4*F4-G4) | K4: =IF(OR(B4="",C4=""),"",0) | L4: =IF(OR(B4="",C4=""),"",0) | M4: =IF(K4=0,0,L4/K4) | N4: =IF(H4<0,ABS(H4)*(F4-M4)-G4,0) | O4: =IF(H4="","",IF(H4>0,L4+I4+G4,MAX(0,L4-ABS(H4)*M4))) | P4: =IF(H4="","",K4+H4) | Q4: =IF(P4=0,0,O4/P4) | R4: 初始持仓 | S4: =IF(H4="","",IF(P4<0,"ERROR: Over-sold",IF(AND(H4<0,K4=0),"ERROR: Sell w/o position","")))
A5: 46037 | B5: SOXX | C5: L1 | D5: Buy | E5: 31 | F5: 321.72 | H5: =IF(OR(D5="",E5=""),"",IF(D5="BUY",E5,-E5)) | I5: =IF(H5="","",ABS(H5)*F5) | J5: =IF(H5="","",-H5*F5-G5) | K5: =IF(OR(B5="",C5=""),"",SUMIFS($H$4:H4,$B$4:B4,B5,$C$4:C4,C5)) | L5: =IF(OR(B5="",C5=""),"",IFERROR(LOOKUP(2,1/(($B$4:B4=B5)*($C$4:C4=C5)),$O$4:O4),0)) | M5: =IF(K5=0,0,L5/K5) | N5: =IF(H5<0,ABS(H5)*(F5-M5)-G5,0) | O5: =IF(H5="","",IF(H5>0,L5+I5+G5,MAX(0,L5-ABS(H5)*M5))) | P5: =IF(H5="","",K5+H5) | Q5: =IF(P5=0,0,O5/P5) | R5: 初始持仓 | S5: =IF(H5="","",IF(P5<0,"ERROR: Over-sold",IF(AND(H5<0,K5=0),"ERROR: Sell w/o position","")))
A6: 46038 | B6: JEPQ | C6: L0+ | D6: BUY | E6: 1151 | F6: 59.15 | G6: 14.25 | H6: =IF(OR(D6="",E6=""),"",IF(D6="BUY",E6,-E6)) | I6: =IF(H6="","",ABS(H6)*F6) | J6: =IF(H6="","",-H6*F6-G6) | K6: =IF(OR(B6="",C6=""),"",SUMIFS($H$4:H5,$B$4:B5,B6,$C$4:C5,C6)) | L6: =IF(OR(B6="",C6=""),"",IFERROR(LOOKUP(2,1/(($B$4:B5=B6)*($C$4:C5=C6)),$O$4:O5),0)) | M6: =IF(K6=0,0,L6/K6) | N6: =IF(H6<0,ABS(H6)*(F6-M6)-G6,0) | O6: =IF(H6="","",IF(H6>0,L6+I6+G6,MAX(0,L6-ABS(H6)*M6))) | P6: =IF(H6="","",K6+H6) | Q6: =IF(P6=0,0,O6/P6) | S6: =IF(H6="","",IF(P6<0,"ERROR: Over-sold",IF(AND(H6<0,K6=0),"ERROR: Sell w/o position","")))
A7: 46038 | B7: JEPQ | C7: L0+ | D7: BUY | E7: 50 | F7: 59.14 | H7: =IF(OR(D7="",E7=""),"",IF(D7="BUY",E7,-E7)) | I7: =IF(H7="","",ABS(H7)*F7) | J7: =IF(H7="","",-H7*F7-G7) | K7: =IF(OR(B7="",C7=""),"",SUMIFS($H$4:H6,$B$4:B6,B7,$C$4:C6,C7)) | L7: =IF(OR(B7="",C7=""),"",IFERROR(LOOKUP(2,1/(($B$4:B6=B7)*($C$4:C6=C7)),$O$4:O6),0)) | M7: =IF(K7=0,0,L7/K7) | N7: =IF(H7<0,ABS(H7)*(F7-M7)-G7,0) | O7: =IF(H7="","",IF(H7>0,L7+I7+G7,MAX(0,L7-ABS(H7)*M7))) | P7: =IF(H7="","",K7+H7) | Q7: =IF(P7=0,0,O7/P7) | S7: =IF(H7="","",IF(P7<0,"ERROR: Over-sold",IF(AND(H7<0,K7=0),"ERROR: Sell w/o position","")))
A8: 46038 | B8: JEPQ | C8: L0+ | D8: SELL | E8: 152 | F8: 59.12 | G8: 2.58 | H8: =IF(OR(D8="",E8=""),"",IF(D8="BUY",E8,-E8)) | I8: =IF(H8="","",ABS(H8)*F8) | J8: =IF(H8="","",-H8*F8-G8) | K8: =IF(OR(B8="",C8=""),"",SUMIFS($H$4:H7,$B$4:B7,B8,$C$4:C7,C8)) | L8: =IF(OR(B8="",C8=""),"",IFERROR(LOOKUP(2,1/(($B$4:B7=B8)*($C$4:C7=C8)),$O$4:O7),0)) | M8: =IF(K8=0,0,L8/K8) | N8: =IF(H8<0,ABS(H8)*(F8-M8)-G8,0) | O8: =IF(H8="","",IF(H8>0,L8+I8+G8,MAX(0,L8-ABS(H8)*M8))) | P8: =IF(H8="","",K8+H8) | Q8: =IF(P8=0,0,O8/P8) | R8: 持仓比例超出，立刻卖出 | S8: =IF(H8="","",IF(P8<0,"ERROR: Over-sold",IF(AND(H8<0,K8=0),"ERROR: Sell w/o position","")))
A9: 46038 | B9: SPY | C9: L1 | D9: BUY | E9: 13 | F9: 693.7 | G9: 2.04 | H9: =IF(OR(D9="",E9=""),"",IF(D9="BUY",E9,-E9)) | I9: =IF(H9="","",ABS(H9)*F9) | J9: =IF(H9="","",-H9*F9-G9) | K9: =IF(OR(B9="",C9=""),"",SUMIFS($H$4:H8,$B$4:B8,B9,$C$4:C8,C9)) | L9: =IF(OR(B9="",C9=""),"",IFERROR(LOOKUP(2,1/(($B$4:B8=B9)*($C$4:C8=C9)),$O$4:O8),0)) | M9: =IF(K9=0,0,L9/K9) | N9: =IF(H9<0,ABS(H9)*(F9-M9)-G9,0) | O9: =IF(H9="","",IF(H9>0,L9+I9+G9,MAX(0,L9-ABS(H9)*M9))) | P9: =IF(H9="","",K9+H9) | Q9: =IF(P9=0,0,O9/P9) | S9: =IF(H9="","",IF(P9<0,"ERROR: Over-sold",IF(AND(H9<0,K9=0),"ERROR: Sell w/o position","")))
A10: 46042 | B10: JEPQ | C10: L0+ | D10: BUY | E10: 94 | F10: 58.7 | G10: 2.36 | H10: =IF(OR(D10="",E10=""),"",IF(D10="BUY",E10,-E10)) | I10: =IF(H10="","",ABS(H10)*F10) | J10: =IF(H10="","",-H10*F10-G10) | K10: =IF(OR(B10="",C10=""),"",SUMIFS($H$4:H9,$B$4:B9,B10,$C$4:C9,C10)) | L10: =IF(OR(B10="",C10=""),"",IFERROR(LOOKUP(2,1/(($B$4:B9=B10)*($C$4:C9=C10)),$O$4:O9),0)) | M10: =IF(K10=0,0,L10/K10) | N10: =IF(H10<0,ABS(H10)*(F10-M10)-G10,0) | O10: =IF(H10="","",IF(H10>0,L10+I10+G10,MAX(0,L10-ABS(H10)*M10))) | P10: =IF(H10="","",K10+H10) | Q10: =IF(P10=0,0,O10/P10) | S10: =IF(H10="","",IF(P10<0,"ERROR: Over-sold",IF(AND(H10<0,K10=0),"ERROR: Sell w/o position","")))
A11: 46043 | B11: SPY | C11: L1 | D11: SELL | E11: 15.00482 | F11: 682.59 | G11: 2.05 | H11: =IF(OR(D11="",E11=""),"",IF(D11="BUY",E11,-E11)) | I11: =IF(H11="","",ABS(H11)*F11) | J11: =IF(H11="","",-H11*F11-G11) | K11: =IF(OR(B11="",C11=""),"",SUMIFS($H$4:H10,$B$4:B10,B11,$C$4:C10,C11)) | L11: =IF(OR(B11="",C11=""),"",IFERROR(LOOKUP(2,1/(($B$4:B10=B11)*($C$4:C10=C11)),$O$4:O10),0)) | M11: =IF(K11=0,0,L11/K11) | N11: =IF(H11<0,ABS(H11)*(F11-M11)-G11,0) | O11: =IF(H11="","",IF(H11>0,L11+I11+G11,MAX(0,L11-ABS(H11)*M11))) | P11: =IF(H11="","",K11+H11) | Q11: =IF(P11=0,0,O11/P11) | S11: =IF(H11="","",IF(P11<0,"ERROR: Over-sold",IF(AND(H11<0,K11=0),"ERROR: Sell w/o position","")))
A12: 46045 | B12: JEPQ | C12: L0+ | D12: BUY | E12: 245 | F12: 58.94 | G12: 2.95 | H12: =IF(OR(D12="",E12=""),"",IF(D12="BUY",E12,-E12)) | I12: =IF(H12="","",ABS(H12)*F12) | J12: =IF(H12="","",-H12*F12-G12) | K12: =IF(OR(B12="",C12=""),"",SUMIFS($H$4:H11,$B$4:B11,B12,$C$4:C11,C12)) | L12: =IF(OR(B12="",C12=""),"",IFERROR(LOOKUP(2,1/(($B$4:B11=B12)*($C$4:C11=C12)),$O$4:O11),0)) | M12: =IF(K12=0,0,L12/K12) | N12: =IF(H12<0,ABS(H12)*(F12-M12)-G12,0) | O12: =IF(H12="","",IF(H12>0,L12+I12+G12,MAX(0,L12-ABS(H12)*M12))) | P12: =IF(H12="","",K12+H12) | Q12: =IF(P12=0,0,O12/P12) | S12: =IF(H12="","",IF(P12<0,"ERROR: Over-sold",IF(AND(H12<0,K12=0),"ERROR: Sell w/o position","")))
A13: 46045 | B13: JEPQ | C13: L0+ | D13: SELL | E13: 728 | F13: 59.33 | G13: 8.63 | H13: =IF(OR(D13="",E13=""),"",IF(D13="BUY",E13,-E13)) | I13: =IF(H13="","",ABS(H13)*F13) | J13: =IF(H13="","",-H13*F13-G13) | K13: =IF(OR(B13="",C13=""),"",SUMIFS($H$4:H12,$B$4:B12,B13,$C$4:C12,C13)) | L13: =IF(OR(B13="",C13=""),"",IFERROR(LOOKUP(2,1/(($B$4:B12=B13)*($C$4:C12=C13)),$O$4:O12),0)) | M13: =IF(K13=0,0,L13/K13) | N13: =IF(H13<0,ABS(H13)*(F13-M13)-G13,0) | O13: =IF(H13="","",IF(H13>0,L13+I13+G13,MAX(0,L13-ABS(H13)*M13))) | P13: =IF(H13="","",K13+H13) | Q13: =IF(P13=0,0,O13/P13) | R13: 调整持仓比例 | S13: =IF(H13="","",IF(P13<0,"ERROR: Over-sold",IF(AND(H13<0,K13=0),"ERROR: Sell w/o position","")))
A14: 46045 | B14: QUAL | C14: L0+ | D14: BUY | E14: 128 | F14: 203.14 | G14: 2.49 | H14: =IF(OR(D14="",E14=""),"",IF(D14="BUY",E14,-E14)) | I14: =IF(H14="","",ABS(H14)*F14) | J14: =IF(H14="","",-H14*F14-G14) | K14: =IF(OR(B14="",C14=""),"",SUMIFS($H$4:H13,$B$4:B13,B14,$C$4:C13,C14)) | L14: =IF(OR(B14="",C14=""),"",IFERROR(LOOKUP(2,1/(($B$4:B13=B14)*($C$4:C13=C14)),$O$4:O13),0)) | M14: =IF(K14=0,0,L14/K14) | N14: =IF(H14<0,ABS(H14)*(F14-M14)-G14,0) | O14: =IF(H14="","",IF(H14>0,L14+I14+G14,MAX(0,L14-ABS(H14)*M14))) | P14: =IF(H14="","",K14+H14) | Q14: =IF(P14=0,0,O14/P14) | S14: =IF(H14="","",IF(P14<0,"ERROR: Over-sold",IF(AND(H14<0,K14=0),"ERROR: Sell w/o position","")))
A15: 46050 | B15: QQQ | C15: L1 | D15: BUY | E15: 15 | F15: 635.88 | G15: 2.05 | H15: =IF(OR(D15="",E15=""),"",IF(D15="BUY",E15,-E15)) | I15: =IF(H15="","",ABS(H15)*F15) | J15: =IF(H15="","",-H15*F15-G15) | K15: =IF(OR(B15="",C15=""),"",SUMIFS($H$4:H14,$B$4:B14,B15,$C$4:C14,C15)) | L15: =IF(OR(B15="",C15=""),"",IFERROR(LOOKUP(2,1/(($B$4:B14=B15)*($C$4:C14=C15)),$O$4:O14),0)) | M15: =IF(K15=0,0,L15/K15) | N15: =IF(H15<0,ABS(H15)*(F15-M15)-G15,0) | O15: =IF(H15="","",IF(H15>0,L15+I15+G15,MAX(0,L15-ABS(H15)*M15))) | P15: =IF(H15="","",K15+H15) | Q15: =IF(P15=0,0,O15/P15) | S15: =IF(H15="","",IF(P15<0,"ERROR: Over-sold",IF(AND(H15<0,K15=0),"ERROR: Sell w/o position","")))
A16: 46059 | B16: QQQ | C16: L1 | D16: SELL | E16: 15 | F16: 599.3 | G16: 2.05 | H16: =IF(OR(D16="",E16=""),"",IF(D16="BUY",E16,-E16)) | I16: =IF(H16="","",ABS(H16)*F16) | J16: =IF(H16="","",-H16*F16-G16) | K16: =IF(OR(B16="",C16=""),"",SUMIFS($H$4:H15,$B$4:B15,B16,$C$4:C15,C16)) | L16: =IF(OR(B16="",C16=""),"",IFERROR(LOOKUP(2,1/(($B$4:B15=B16)*($C$4:C15=C16)),$O$4:O15),0)) | M16: =IF(K16=0,0,L16/K16) | N16: =IF(H16<0,ABS(H16)*(F16-M16)-G16,0) | O16: =IF(H16="","",IF(H16>0,L16+I16+G16,MAX(0,L16-ABS(H16)*M16))) | P16: =IF(H16="","",K16+H16) | Q16: =IF(P16=0,0,O16/P16) | S16: =IF(H16="","",IF(P16<0,"ERROR: Over-sold",IF(AND(H16<0,K16=0),"ERROR: Sell w/o position","")))
A17: 46059 | B17: SOXX | C17: L1 | D17: SELL | E17: 31 | F17: 336.55 | G17: 2.11 | H17: =IF(OR(D17="",E17=""),"",IF(D17="BUY",E17,-E17)) | I17: =IF(H17="","",ABS(H17)*F17) | J17: =IF(H17="","",-H17*F17-G17) | K17: =IF(OR(B17="",C17=""),"",SUMIFS($H$4:H16,$B$4:B16,B17,$C$4:C16,C17)) | L17: =IF(OR(B17="",C17=""),"",IFERROR(LOOKUP(2,1/(($B$4:B16=B17)*($C$4:C16=C17)),$O$4:O16),0)) | M17: =IF(K17=0,0,L17/K17) | N17: =IF(H17<0,ABS(H17)*(F17-M17)-G17,0) | O17: =IF(H17="","",IF(H17>0,L17+I17+G17,MAX(0,L17-ABS(H17)*M17))) | P17: =IF(H17="","",K17+H17) | Q17: =IF(P17=0,0,O17/P17) | S17: =IF(H17="","",IF(P17<0,"ERROR: Over-sold",IF(AND(H17<0,K17=0),"ERROR: Sell w/o position","")))
A18: 46060 | B18: JEPQ | C18: L0+ | D18: BUY | E18: 4.77541 | F18: 57.93 | G18: 2.01 | H18: =IF(OR(D18="",E18=""),"",IF(D18="BUY",E18,-E18)) | I18: =IF(H18="","",ABS(H18)*F18) | J18: =IF(H18="","",-H18*F18-G18) | K18: =IF(OR(B18="",C18=""),"",SUMIFS($H$4:H17,$B$4:B17,B18,$C$4:C17,C18)) | L18: =IF(OR(B18="",C18=""),"",IFERROR(LOOKUP(2,1/(($B$4:B17=B18)*($C$4:C17=C18)),$O$4:O17),0)) | M18: =IF(K18=0,0,L18/K18) | N18: =IF(H18<0,ABS(H18)*(F18-M18)-G18,0) | O18: =IF(H18="","",IF(H18>0,L18+I18+G18,MAX(0,L18-ABS(H18)*M18))) | P18: =IF(H18="","",K18+H18) | Q18: =IF(P18=0,0,O18/P18) | R18: 红利复投 | S18: =IF(H18="","",IF(P18<0,"ERROR: Over-sold",IF(AND(H18<0,K18=0),"ERROR: Sell w/o position","")))
A19: 46079 | B19: SOXX | C19: L1 | D19: BUY | E19: 28 | F19: 366.88 | G19: 2.1 | H19: =IF(OR(D19="",E19=""),"",IF(D19="BUY",E19,-E19)) | I19: =IF(H19="","",ABS(H19)*F19) | J19: =IF(H19="","",-H19*F19-G19) | K19: =IF(OR(B19="",C19=""),"",SUMIFS($H$4:H18,$B$4:B18,B19,$C$4:C18,C19)) | L19: =IF(OR(B19="",C19=""),"",IFERROR(LOOKUP(2,1/(($B$4:B18=B19)*($C$4:C18=C19)),$O$4:O18),0)) | M19: =IF(K19=0,0,L19/K19) | N19: =IF(H19<0,ABS(H19)*(F19-M19)-G19,0) | O19: =IF(H19="","",IF(H19>0,L19+I19+G19,MAX(0,L19-ABS(H19)*M19))) | P19: =IF(H19="","",K19+H19) | Q19: =IF(P19=0,0,O19/P19) | S19: =IF(H19="","",IF(P19<0,"ERROR: Over-sold",IF(AND(H19<0,K19=0),"ERROR: Sell w/o position","")))
A20: 46085 | B20: SOXX | C20: L1 | D20: SELL | E20: 28 | F20: 329.01 | G20: 2.1 | H20: =IF(OR(D20="",E20=""),"",IF(D20="BUY",E20,-E20)) | I20: =IF(H20="","",ABS(H20)*F20) | J20: =IF(H20="","",-H20*F20-G20) | K20: =IF(OR(B20="",C20=""),"",SUMIFS($H$4:H19,$B$4:B19,B20,$C$4:C19,C20)) | L20: =IF(OR(B20="",C20=""),"",IFERROR(LOOKUP(2,1/(($B$4:B19=B20)*($C$4:C19=C20)),$O$4:O19),0)) | M20: =IF(K20=0,0,L20/K20) | N20: =IF(H20<0,ABS(H20)*(F20-M20)-G20,0) | O20: =IF(H20="","",IF(H20>0,L20+I20+G20,MAX(0,L20-ABS(H20)*M20))) | P20: =IF(H20="","",K20+H20) | Q20: =IF(P20=0,0,O20/P20) | S20: =IF(H20="","",IF(P20<0,"ERROR: Over-sold",IF(AND(H20<0,K20=0),"ERROR: Sell w/o position","")))
A21: 46088 | B21: JEPQ | C21: L0+ | D21: BUY | E21: 5.32394 | F21: 57.18 | G21: 2.01 | H21: =IF(OR(D21="",E21=""),"",IF(D21="BUY",E21,-E21)) | I21: =IF(H21="","",ABS(H21)*F21) | J21: =IF(H21="","",-H21*F21-G21) | K21: =IF(OR(B21="",C21=""),"",SUMIFS($H$4:H20,$B$4:B20,B21,$C$4:C20,C21)) | L21: =IF(OR(B21="",C21=""),"",IFERROR(LOOKUP(2,1/(($B$4:B20=B21)*($C$4:C20=C21)),$O$4:O20),0)) | M21: =IF(K21=0,0,L21/K21) | N21: =IF(H21<0,ABS(H21)*(F21-M21)-G21,0) | O21: =IF(H21="","",IF(H21>0,L21+I21+G21,MAX(0,L21-ABS(H21)*M21))) | P21: =IF(H21="","",K21+H21) | Q21: =IF(P21=0,0,O21/P21) | R21: 红利复投
A22: 46105 | B22: QUAL | C22: L0+ | D22: BUY | E22: 0.24931 | F22: 194.01 | G22: 0.48 | H22: =IF(OR(D22="",E22=""),"",IF(D22="BUY",E22,-E22)) | I22: =IF(H22="","",ABS(H22)*F22) | J22: =IF(H22="","",-H22*F22-G22) | K22: =IF(OR(B22="",C22=""),"",SUMIFS($H$4:H20,$B$4:B20,B22,$C$4:C20,C22)) | L22: =IF(OR(B22="",C22=""),"",IFERROR(LOOKUP(2,1/(($B$4:B20=B22)*($C$4:C20=C22)),$O$4:O20),0)) | M22: =IF(K22=0,0,L22/K22) | N22: =IF(H22<0,ABS(H22)*(F22-M22)-G22,0) | O22: =IF(H22="","",IF(H22>0,L22+I22+G22,MAX(0,L22-ABS(H22)*M22))) | P22: =IF(H22="","",K22+H22) | Q22: =IF(P22=0,0,O22/P22) | R22: 红利复投 | S22: =IF(H22="","",IF(P22<0,"ERROR: Over-sold",IF(AND(H22<0,K22=0),"ERROR: Sell w/o position","")))
A23: 46120 | B23: JEPQ | C23: L0+ | D23: BUY | E23: 6.06026 | F23: 55.58 | G23: 2.01 | H23: =IF(OR(D23="",E23=""),"",IF(D23="BUY",E23,-E23)) | I23: =IF(H23="","",ABS(H23)*F23) | J23: =IF(H23="","",-H23*F23-G23) | K23: =IF(OR(B23="",C23=""),"",SUMIFS($H$4:H21,$B$4:B21,B23,$C$4:C21,C23)) | L23: =IF(OR(B23="",C23=""),"",IFERROR(LOOKUP(2,1/(($B$4:B21=B23)*($C$4:C21=C23)),$O$4:O21),0)) | M23: =IF(K23=0,0,L23/K23) | N23: =IF(H23<0,ABS(H23)*(F23-M23)-G23,0) | O23: =IF(H23="","",IF(H23>0,L23+I23+G23,MAX(0,L23-ABS(H23)*M23))) | P23: =IF(H23="","",K23+H23) | Q23: =IF(P23=0,0,O23/P23) | R23: 红利复投
A24: 46121 | B24: SOXX | C24: L1 | D24: BUY | E24: 26 | F24: 373.79 | G24: 2.09 | H24: =IF(OR(D24="",E24=""),"",IF(D24="BUY",E24,-E24)) | I24: =IF(H24="","",ABS(H24)*F24) | J24: =IF(H24="","",-H24*F24-G24) | K24: =IF(OR(B24="",C24=""),"",SUMIFS($H$4:H22,$B$4:B22,B24,$C$4:C22,C24)) | L24: =IF(OR(B24="",C24=""),"",IFERROR(LOOKUP(2,1/(($B$4:B22=B24)*($C$4:C22=C24)),$O$4:O22),0)) | M24: =IF(K24=0,0,L24/K24) | N24: =IF(H24<0,ABS(H24)*(F24-M24)-G24,0) | O24: =IF(H24="","",IF(H24>0,L24+I24+G24,MAX(0,L24-ABS(H24)*M24))) | P24: =IF(H24="","",K24+H24) | Q24: =IF(P24=0,0,O24/P24) | S24: =IF(H24="","",IF(P24<0,"ERROR: Over-sold",IF(AND(H24<0,K24=0),"ERROR: Sell w/o position","")))
A25: 46127 | B25: SPY | C25: L1 | D25: BUY | E25: 14 | F25: 695.17 | G25: 2.04 | H25: =IF(OR(D25="",E25=""),"",IF(D25="BUY",E25,-E25)) | I25: =IF(H25="","",ABS(H25)*F25) | J25: =IF(H25="","",-H25*F25-G25) | K25: =IF(OR(B25="",C25=""),"",SUMIFS($H$4:H24,$B$4:B24,B25,$C$4:C24,C25)) | L25: =IF(OR(B25="",C25=""),"",IFERROR(LOOKUP(2,1/(($B$4:B24=B25)*($C$4:C24=C25)),$O$4:O24),0)) | M25: =IF(K25=0,0,L25/K25) | N25: =IF(H25<0,ABS(H25)*(F25-M25)-G25,0) | O25: =IF(H25="","",IF(H25>0,L25+I25+G25,MAX(0,L25-ABS(H25)*M25))) | P25: =IF(H25="","",K25+H25) | Q25: =IF(P25=0,0,O25/P25) | S25: =IF(H25="","",IF(P25<0,"ERROR: Over-sold",IF(AND(H25<0,K25=0),"ERROR: Sell w/o position","")))
A26: 46127 | B26: QQQ | C26: L1 | D26: BUY | E26: 6 | F26: 628.74 | G26: 2.01 | H26: =IF(OR(D26="",E26=""),"",IF(D26="BUY",E26,-E26)) | I26: =IF(H26="","",ABS(H26)*F26) | J26: =IF(H26="","",-H26*F26-G26) | K26: =IF(OR(B26="",C26=""),"",SUMIFS($H$4:H25,$B$4:B25,B26,$C$4:C25,C26)) | L26: =IF(OR(B26="",C26=""),"",IFERROR(LOOKUP(2,1/(($B$4:B25=B26)*($C$4:C25=C26)),$O$4:O25),0)) | M26: =IF(K26=0,0,L26/K26) | N26: =IF(H26<0,ABS(H26)*(F26-M26)-G26,0) | O26: =IF(H26="","",IF(H26>0,L26+I26+G26,MAX(0,L26-ABS(H26)*M26))) | P26: =IF(H26="","",K26+H26) | Q26: =IF(P26=0,0,O26/P26) | S26: =IF(H26="","",IF(P26<0,"ERROR: Over-sold",IF(AND(H26<0,K26=0),"ERROR: Sell w/o position","")))
A27: 46127 | B27: JEPQ | C27: L0+ | D27: SELL | E27: 100.15961 | F27: 58.44 | G27: 2.51 | H27: =IF(OR(D27="",E27=""),"",IF(D27="BUY",E27,-E27)) | I27: =IF(H27="","",ABS(H27)*F27) | J27: =IF(H27="","",-H27*F27-G27) | K27: =IF(OR(B27="",C27=""),"",SUMIFS($H$4:H26,$B$4:B26,B27,$C$4:C26,C27)) | L27: =IF(OR(B27="",C27=""),"",IFERROR(LOOKUP(2,1/(($B$4:B26=B27)*($C$4:C26=C27)),$O$4:O26),0)) | M27: =IF(K27=0,0,L27/K27) | N27: =IF(H27<0,ABS(H27)*(F27-M27)-G27,0) | O27: =IF(H27="","",IF(H27>0,L27+I27+G27,MAX(0,L27-ABS(H27)*M27))) | P27: =IF(H27="","",K27+H27) | Q27: =IF(P27=0,0,O27/P27) | R27: 调整持仓比例 | S27: =IF(H27="","",IF(P27<0,"ERROR: Over-sold",IF(AND(H27<0,K27=0),"ERROR: Sell w/o position","")))
A28: 46127 | B28: JEPQ | C28: L0+ | D28: SELL | E28: 26 | F28: 58.43 | G28: 2.12 | H28: =IF(OR(D28="",E28=""),"",IF(D28="BUY",E28,-E28)) | I28: =IF(H28="","",ABS(H28)*F28) | J28: =IF(H28="","",-H28*F28-G28) | K28: =IF(OR(B28="",C28=""),"",SUMIFS($H$4:H27,$B$4:B27,B28,$C$4:C27,C28)) | L28: =IF(OR(B28="",C28=""),"",IFERROR(LOOKUP(2,1/(($B$4:B27=B28)*($C$4:C27=C28)),$O$4:O27),0)) | M28: =IF(K28=0,0,L28/K28) | N28: =IF(H28<0,ABS(H28)*(F28-M28)-G28,0) | O28: =IF(H28="","",IF(H28>0,L28+I28+G28,MAX(0,L28-ABS(H28)*M28))) | P28: =IF(H28="","",K28+H28) | Q28: =IF(P28=0,0,O28/P28) | R28: 调整持仓比例 | S28: =IF(H28="","",IF(P28<0,"ERROR: Over-sold",IF(AND(H28<0,K28=0),"ERROR: Sell w/o position","")))
A29: 46127 | B29: QQQ | C29: L1 | D29: BUY | E29: 10 | F29: 629.37 | G29: 2.03 | H29: =IF(OR(D29="",E29=""),"",IF(D29="BUY",E29,-E29)) | I29: =IF(H29="","",ABS(H29)*F29) | J29: =IF(H29="","",-H29*F29-G29) | K29: =IF(OR(B29="",C29=""),"",SUMIFS($H$4:H28,$B$4:B28,B29,$C$4:C28,C29)) | L29: =IF(OR(B29="",C29=""),"",IFERROR(LOOKUP(2,1/(($B$4:B28=B29)*($C$4:C28=C29)),$O$4:O28),0)) | M29: =IF(K29=0,0,L29/K29) | N29: =IF(H29<0,ABS(H29)*(F29-M29)-G29,0) | O29: =IF(H29="","",IF(H29>0,L29+I29+G29,MAX(0,L29-ABS(H29)*M29))) | P29: =IF(H29="","",K29+H29) | Q29: =IF(P29=0,0,O29/P29) | S29: =IF(H29="","",IF(P29<0,"ERROR: Over-sold",IF(AND(H29<0,K29=0),"ERROR: Sell w/o position","")))
A30: 46127 | B30: QQQ | C30: L1 | D30: BUY | E30: 10 | F30: 629.3 | G30: 2.03 | H30: =IF(OR(D30="",E30=""),"",IF(D30="BUY",E30,-E30)) | I30: =IF(H30="","",ABS(H30)*F30) | J30: =IF(H30="","",-H30*F30-G30) | K30: =IF(OR(B30="",C30=""),"",SUMIFS($H$4:H29,$B$4:B29,B30,$C$4:C29,C30)) | L30: =IF(OR(B30="",C30=""),"",IFERROR(LOOKUP(2,1/(($B$4:B29=B30)*($C$4:C29=C30)),$O$4:O29),0)) | M30: =IF(K30=0,0,L30/K30) | N30: =IF(H30<0,ABS(H30)*(F30-M30)-G30,0) | O30: =IF(H30="","",IF(H30>0,L30+I30+G30,MAX(0,L30-ABS(H30)*M30))) | P30: =IF(H30="","",K30+H30) | Q30: =IF(P30=0,0,O30/P30) | S30: =IF(H30="","",IF(P30<0,"ERROR: Over-sold",IF(AND(H30<0,K30=0),"ERROR: Sell w/o position","")))
A31: 46127 | B31: QQQ | C31: L1 | D31: SELL | E31: 10 | F31: 629.18 | G31: 2.16 | H31: =IF(OR(D31="",E31=""),"",IF(D31="BUY",E31,-E31)) | I31: =IF(H31="","",ABS(H31)*F31) | J31: =IF(H31="","",-H31*F31-G31) | K31: =IF(OR(B31="",C31=""),"",SUMIFS($H$4:H30,$B$4:B30,B31,$C$4:C30,C31)) | L31: =IF(OR(B31="",C31=""),"",IFERROR(LOOKUP(2,1/(($B$4:B30=B31)*($C$4:C30=C31)),$O$4:O30),0)) | M31: =IF(K31=0,0,L31/K31) | N31: =IF(H31<0,ABS(H31)*(F31-M31)-G31,0) | O31: =IF(H31="","",IF(H31>0,L31+I31+G31,MAX(0,L31-ABS(H31)*M31))) | P31: =IF(H31="","",K31+H31) | Q31: =IF(P31=0,0,O31/P31) | R31: 调整持仓比例 | S31: =IF(H31="","",IF(P31<0,"ERROR: Over-sold",IF(AND(H31<0,K31=0),"ERROR: Sell w/o position","")))
A32: 46127 | B32: JEPQ | C32: L0+ | D32: BUY | E32: 189 | F32: 58.38 | G32: 2.73 | H32: =IF(OR(D32="",E32=""),"",IF(D32="BUY",E32,-E32)) | I32: =IF(H32="","",ABS(H32)*F32) | J32: =IF(H32="","",-H32*F32-G32) | K32: =IF(OR(B32="",C32=""),"",SUMIFS($H$4:H31,$B$4:B31,B32,$C$4:C31,C32)) | L32: =IF(OR(B32="",C32=""),"",IFERROR(LOOKUP(2,1/(($B$4:B31=B32)*($C$4:C31=C32)),$O$4:O31),0)) | M32: =IF(K32=0,0,L32/K32) | N32: =IF(H32<0,ABS(H32)*(F32-M32)-G32,0) | O32: =IF(H32="","",IF(H32>0,L32+I32+G32,MAX(0,L32-ABS(H32)*M32))) | P32: =IF(H32="","",K32+H32) | Q32: =IF(P32=0,0,O32/P32) | R32: 调整持仓比例 | S32: =IF(H32="","",IF(P32<0,"ERROR: Over-sold",IF(AND(H32<0,K32=0),"ERROR: Sell w/o position","")))
A33: 46127 | B33: JEPQ | C33: L0+ | D33: SELL | E33: 289 | F33: 58.66 | G33: 3.78 | H33: =IF(OR(D33="",E33=""),"",IF(D33="BUY",E33,-E33)) | I33: =IF(H33="","",ABS(H33)*F33) | J33: =IF(H33="","",-H33*F33-G33) | K33: =IF(OR(B33="",C33=""),"",SUMIFS($H$4:H32,$B$4:B32,B33,$C$4:C32,C33)) | L33: =IF(OR(B33="",C33=""),"",IFERROR(LOOKUP(2,1/(($B$4:B32=B33)*($C$4:C32=C33)),$O$4:O32),0)) | M33: =IF(K33=0,0,L33/K33) | N33: =IF(H33<0,ABS(H33)*(F33-M33)-G33,0) | O33: =IF(H33="","",IF(H33>0,L33+I33+G33,MAX(0,L33-ABS(H33)*M33))) | P33: =IF(H33="","",K33+H33) | Q33: =IF(P33=0,0,O33/P33) | R33: 调整持仓比例 | S33: =IF(H33="","",IF(P33<0,"ERROR: Over-sold",IF(AND(H33<0,K33=0),"ERROR: Sell w/o position","")))
A34: 46130 | B34: JEPQ | C34: L0+ | D34: BUY | E34: 250 | F34: 58.64 | G34: 2.97 | H34: =IF(OR(D34="",E34=""),"",IF(D34="BUY",E34,-E34)) | I34: =IF(H34="","",ABS(H34)*F34) | J34: =IF(H34="","",-H34*F34-G34) | K34: =IF(OR(B34="",C34=""),"",SUMIFS($H$4:H33,$B$4:B33,B34,$C$4:C33,C34)) | L34: =IF(OR(B34="",C34=""),"",IFERROR(LOOKUP(2,1/(($B$4:B33=B34)*($C$4:C33=C34)),$O$4:O33),0)) | M34: =IF(K34=0,0,L34/K34) | N34: =IF(H34<0,ABS(H34)*(F34-M34)-G34,0) | O34: =IF(H34="","",IF(H34>0,L34+I34+G34,MAX(0,L34-ABS(H34)*M34))) | P34: =IF(H34="","",K34+H34) | Q34: =IF(P34=0,0,O34/P34) | R34: 调整持仓比例 | S34: =IF(H34="","",IF(P34<0,"ERROR: Over-sold",IF(AND(H34<0,K34=0),"ERROR: Sell w/o position","")))
A35: 46149 | B35: JEPQ | C35: L0+ | D35: BUY | E35: 6.27067 | F35: 59.36 | G35: 2.01 | H35: =IF(OR(D35="",E35=""),"",IF(D35="BUY",E35,-E35)) | I35: =IF(H35="","",ABS(H35)*F35) | J35: =IF(H35="","",-H35*F35-G35) | K35: =IF(OR(B35="",C35=""),"",SUMIFS($H$4:H34,$B$4:B34,B35,$C$4:C34,C35)) | L35: =IF(OR(B35="",C35=""),"",IFERROR(LOOKUP(2,1/(($B$4:B34=B35)*($C$4:C34=C35)),$O$4:O34),0)) | M35: =IF(K35=0,0,L35/K35) | N35: =IF(H35<0,ABS(H35)*(F35-M35)-G35,0) | O35: =IF(H35="","",IF(H35>0,L35+I35+G35,MAX(0,L35-ABS(H35)*M35))) | P35: =IF(H35="","",K35+H35) | Q35: =IF(P35=0,0,O35/P35) | R35: 红利复投 | S35: =IF(H35="","",IF(P35<0,"ERROR: Over-sold",IF(AND(H35<0,K35=0),"ERROR: Sell w/o position","")))
A36: 46149 | B36: JEPQ | C36: L0+ | D36: BUY | E36: 37 | F36: 59.36 | G36: 2.13 | H36: =IF(OR(D36="",E36=""),"",IF(D36="BUY",E36,-E36)) | I36: =IF(H36="","",ABS(H36)*F36) | J36: =IF(H36="","",-H36*F36-G36) | K36: =IF(OR(B36="",C36=""),"",SUMIFS($H$4:H35,$B$4:B35,B36,$C$4:C35,C36)) | L36: =IF(OR(B36="",C36=""),"",IFERROR(LOOKUP(2,1/(($B$4:B35=B36)*($C$4:C35=C36)),$O$4:O35),0)) | M36: =IF(K36=0,0,L36/K36) | N36: =IF(H36<0,ABS(H36)*(F36-M36)-G36,0) | O36: =IF(H36="","",IF(H36>0,L36+I36+G36,MAX(0,L36-ABS(H36)*M36))) | P36: =IF(H36="","",K36+H36) | Q36: =IF(P36=0,0,O36/P36) | R36: 调整持仓比例
A37: 46161 | B37: SOXX | C37: L1 | D37: SELL | E37: 26 | F37: 478.53 | G37: 2.35 | H37: =IF(OR(D37="",E37=""),"",IF(D37="BUY",E37,-E37)) | I37: =IF(H37="","",ABS(H37)*F37) | J37: =IF(H37="","",-H37*F37-G37) | K37: =IF(OR(B37="",C37=""),"",SUMIFS($H$4:H36,$B$4:B36,B37,$C$4:C36,C37)) | L37: =IF(OR(B37="",C37=""),"",IFERROR(LOOKUP(2,1/(($B$4:B36=B37)*($C$4:C36=C37)),$O$4:O36),0)) | M37: =IF(K37=0,0,L37/K37) | N37: =IF(H37<0,ABS(H37)*(F37-M37)-G37,0) | O37: =IF(H37="","",IF(H37>0,L37+I37+G37,MAX(0,L37-ABS(H37)*M37))) | P37: =IF(H37="","",K37+H37) | Q37: =IF(P37=0,0,O37/P37) | R37: 未能理解策略细节，错误止损 | S37: =IF(H37="","",IF(P37<0,"ERROR: Over-sold",IF(AND(H37<0,K37=0),"ERROR: Sell w/o position","")))
A38: 46162 | B38: SOXX | C38: L1 | D38: BUY | E38: 26 | F38: 515.88 | G38: 2.09 | H38: =IF(OR(D38="",E38=""),"",IF(D38="BUY",E38,-E38)) | I38: =IF(H38="","",ABS(H38)*F38) | J38: =IF(H38="","",-H38*F38-G38) | K38: =IF(OR(B38="",C38=""),"",SUMIFS($H$4:H37,$B$4:B37,B38,$C$4:C37,C38)) | L38: =IF(OR(B38="",C38=""),"",IFERROR(LOOKUP(2,1/(($B$4:B37=B38)*($C$4:C37=C38)),$O$4:O37),0)) | M38: =IF(K38=0,0,L38/K38) | N38: =IF(H38<0,ABS(H38)*(F38-M38)-G38,0) | O38: =IF(H38="","",IF(H38>0,L38+I38+G38,MAX(0,L38-ABS(H38)*M38))) | P38: =IF(H38="","",K38+H38) | Q38: =IF(P38=0,0,O38/P38) | R38: 修正上述错误买回 | S38: =IF(H38="","",IF(P38<0,"ERROR: Over-sold",IF(AND(H38<0,K38=0),"ERROR: Sell w/o position","")))
A39: 46179 | B39: JEPQ | C39: L0+ | D39: BUY | E39: 6.30574 | F39: 59.55 | G39: 2.01 | H39: =IF(OR(D39="",E39=""),"",IF(D39="BUY",E39,-E39)) | I39: =IF(H39="","",ABS(H39)*F39) | J39: =IF(H39="","",-H39*F39-G39) | K39: =IF(OR(B39="",C39=""),"",SUMIFS($H$4:H38,$B$4:B38,B39,$C$4:C38,C39)) | L39: =IF(OR(B39="",C39=""),"",IFERROR(LOOKUP(2,1/(($B$4:B38=B39)*($C$4:C38=C39)),$O$4:O38),0)) | M39: =IF(K39=0,0,L39/K39) | N39: =IF(H39<0,ABS(H39)*(F39-M39)-G39,0) | O39: =IF(H39="","",IF(H39>0,L39+I39+G39,MAX(0,L39-ABS(H39)*M39))) | P39: =IF(H39="","",K39+H39) | Q39: =IF(P39=0,0,O39/P39) | R39: 红利复投 | S39: =IF(H39="","",IF(P39<0,"ERROR: Over-sold",IF(AND(H39<0,K39=0),"ERROR: Sell w/o position","")))
A40: 46181 | B40: QQQ | C40: L1 | D40: SELL | E40: 16 | F40: 716.23 | G40: 2.29 | H40: =IF(OR(D40="",E40=""),"",IF(D40="BUY",E40,-E40)) | I40: =IF(H40="","",ABS(H40)*F40) | J40: =IF(H40="","",-H40*F40-G40) | K40: =IF(OR(B40="",C40=""),"",SUMIFS($H$4:H39,$B$4:B39,B40,$C$4:C39,C40)) | L40: =IF(OR(B40="",C40=""),"",IFERROR(LOOKUP(2,1/(($B$4:B39=B40)*($C$4:C39=C40)),$O$4:O39),0)) | M40: =IF(K40=0,0,L40/K40) | N40: =IF(H40<0,ABS(H40)*(F40-M40)-G40,0) | O40: =IF(H40="","",IF(H40>0,L40+I40+G40,MAX(0,L40-ABS(H40)*M40))) | P40: =IF(H40="","",K40+H40) | Q40: =IF(P40=0,0,O40/P40) | R40: 策略卖出信号 | S40: =IF(H40="","",IF(P40<0,"ERROR: Over-sold",IF(AND(H40<0,K40=0),"ERROR: Sell w/o position","")))
A41: 46181 | B41: SOXX | C41: L1 | D41: SELL | E41: 26 | F41: 566.49 | G41: 2.39 | H41: =IF(OR(D41="",E41=""),"",IF(D41="BUY",E41,-E41)) | I41: =IF(H41="","",ABS(H41)*F41) | J41: =IF(H41="","",-H41*F41-G41) | K41: =IF(OR(B41="",C41=""),"",SUMIFS($H$4:H40,$B$4:B40,B41,$C$4:C40,C41)) | L41: =IF(OR(B41="",C41=""),"",IFERROR(LOOKUP(2,1/(($B$4:B40=B41)*($C$4:C40=C41)),$O$4:O40),0)) | M41: =IF(K41=0,0,L41/K41) | N41: =IF(H41<0,ABS(H41)*(F41-M41)-G41,0) | O41: =IF(H41="","",IF(H41>0,L41+I41+G41,MAX(0,L41-ABS(H41)*M41))) | P41: =IF(H41="","",K41+H41) | Q41: =IF(P41=0,0,O41/P41) | R41: 策略卖出信号 | S41: =IF(H41="","",IF(P41<0,"ERROR: Over-sold",IF(AND(H41<0,K41=0),"ERROR: Sell w/o position","")))
...

Sheet Cash_Flow
A1: External Cash Flow
A3: Date | B3: Type | C3: Amount | D3: Notes
A4: 46038 | B4: Deposit | C4: 2564.9904
A5: 46042 | B5: Deposit | C5: 1538.5207
A6: 46100 | B6: Deposit | C6: 638.25985
A7: 46148 | B7: Deposit | C7: 4451.1317
A8: 46154 | B8: Deposit | C8: 2937.9982

Sheet Holdings
A1: Current Holdings
A3: Level | B3: Ticker | C3: Qty | D3: Cost Basis | E3: Avg Cost | F3: Last Price | G3: Market Value | H3: Unrealized PnL | I3: Weight
A4: L0+ | B4: JEPQ | C4: =SUMIFS(Transactions!$H:$H,Transactions!$B:$B,B4,Transactions!$C:$C,A4) | D4: =IFERROR(LOOKUP(2,1/((Transactions!$B$4:$B$206=B4)*(Transactions!$C$4:$C$206=A4)),Transactions!$O$4:$O$206),0) | E4: =IF(C4=0,0,D4/C4) | F4: =IFERROR(VLOOKUP(B4,Prices!$A$4:$B$9,2,FALSE),0) | G4: =C4*F4 | H4: =G4-D4 | I4: =IF($B$16=0,0,G4/$B$16)
A5: L0+ | B5: QUAL | C5: =SUMIFS(Transactions!$H:$H,Transactions!$B:$B,B5,Transactions!$C:$C,A5) | D5: =IFERROR(LOOKUP(2,1/((Transactions!$B$4:$B$206=B5)*(Transactions!$C$4:$C$206=A5)),Transactions!$O$4:$O$206),0) | E5: =IF(C5=0,0,D5/C5) | F5: =IFERROR(VLOOKUP(B5,Prices!$A$4:$B$9,2,FALSE),0) | G5: =C5*F5 | H5: =G5-D5 | I5: =IF($B$16=0,0,G5/$B$16)
A6: L1 | B6: SPY | C6: =SUMIFS(Transactions!$H:$H,Transactions!$B:$B,B6,Transactions!$C:$C,A6) | D6: =IFERROR(LOOKUP(2,1/((Transactions!$B$4:$B$206=B6)*(Transactions!$C$4:$C$206=A6)),Transactions!$O$4:$O$206),0) | E6: =IF(C6=0,0,D6/C6) | F6: =IFERROR(VLOOKUP(B6,Prices!$A$4:$B$9,2,FALSE),0) | G6: =C6*F6 | H6: =G6-D6 | I6: =IF($B$16=0,0,G6/$B$16)
A7: L1 | B7: QQQ | C7: =SUMIFS(Transactions!$H:$H,Transactions!$B:$B,B7,Transactions!$C:$C,A7) | D7: =IFERROR(LOOKUP(2,1/((Transactions!$B$4:$B$206=B7)*(Transactions!$C$4:$C$206=A7)),Transactions!$O$4:$O$206),0) | E7: =IF(C7=0,0,D7/C7) | F7: =IFERROR(VLOOKUP(B7,Prices!$A$4:$B$9,2,FALSE),0) | G7: =C7*F7 | H7: =G7-D7 | I7: =IF($B$16=0,0,G7/$B$16)
A8: L1 | B8: SOXX | C8: =SUMIFS(Transactions!$H:$H,Transactions!$B:$B,B8,Transactions!$C:$C,A8) | D8: =IFERROR(LOOKUP(2,1/((Transactions!$B$4:$B$206=B8)*(Transactions!$C$4:$C$206=A8)),Transactions!$O$4:$O$206),0) | E8: =IF(C8=0,0,D8/C8) | F8: =IFERROR(VLOOKUP(B8,Prices!$A$4:$B$9,2,FALSE),0) | G8: =C8*F8 | H8: =G8-D8 | I8: =IF($B$16=0,0,G8/$B$16)
A9: L2 | B9: QQQ | C9: =SUMIFS(Transactions!$H:$H,Transactions!$B:$B,B9,Transactions!$C:$C,A9) | D9: =IFERROR(LOOKUP(2,1/((Transactions!$B$4:$B$206=B9)*(Transactions!$C$4:$C$206=A9)),Transactions!$O$4:$O$206),0) | E9: =IF(C9=0,0,D9/C9) | F9: =IFERROR(VLOOKUP(B9,Prices!$A$4:$B$9,2,FALSE),0) | G9: =C9*F9 | H9: =G9-D9 | I9: =IF($B$16=0,0,G9/$B$16)
A10: L2 | B10: SOXX | C10: =SUMIFS(Transactions!$H:$H,Transactions!$B:$B,B10,Transactions!$C:$C,A10) | D10: =IFERROR(LOOKUP(2,1/((Transactions!$B$4:$B$206=B10)*(Transactions!$C$4:$C$206=A10)),Transactions!$O$4:$O$206),0) | E10: =IF(C10=0,0,D10/C10) | F10: =IFERROR(VLOOKUP(B10,Prices!$A$4:$B$9,2,FALSE),0) | G10: =C10*F10 | H10: =G10-D10 | I10: =IF($B$16=0,0,G10/$B$16)
A11: L2 | B11: TQQQ | C11: =SUMIFS(Transactions!$H:$H,Transactions!$B:$B,B11,Transactions!$C:$C,A11) | D11: =IFERROR(LOOKUP(2,1/((Transactions!$B$4:$B$206=B11)*(Transactions!$C$4:$C$206=A11)),Transactions!$O$4:$O$206),0) | E11: =IF(C11=0,0,D11/C11) | F11: =IFERROR(VLOOKUP(B11,Prices!$A$4:$B$9,2,FALSE),0) | G11: =C11*F11 | H11: =G11-D11 | I11: =IF($B$16=0,0,G11/$B$16)
A15: Cash | B15: =Config!$B$4+SUM(Transactions!$J$4:$J$206)+SUMIFS(Cash_Flow!$C:$C,Cash_Flow!$B:$B,"Deposit")-SUMIFS(Cash_Flow!$C:$C,Cash_Flow!$B:$B,"Withdrawal")
A16: Total Equity | B16: =SUM(G4:G11)+B15

Sheet Daily_Equity
A1: Broker Equity Curve
A3: Date | B3: Strategy Equity / 策略净值 (自动计算) | C3: High Water Mark | D3: Drawdown | E3: Total Brokerage Equity / 券商总净值 (手动输入) | F3: Accumulated HK PnL / 港股打新累计盈亏 (自动匹配)
A4: 46038 | B4: =IF(E4="","",E4-F4) | C4: =IF(B4="","",MAX($B$4:B4)) | D4: =IF(OR(B4="",C4=0),"",B4/C4-1) | E4: 101640.09 | F4: =IFERROR(VLOOKUP(A4, HK_IPO!A:C, 3, TRUE), 0)
A5: 46039 | B5: =IF(E5="","",E5-F5) | C5: =IF(B5="","",MAX($B$4:B5)) | D5: =IF(OR(B5="",C5=0),"",B5/C5-1) | E5: 101639.92 | F5: =IFERROR(VLOOKUP(A5, HK_IPO!A:C, 3, TRUE), 0)
A6: 46040 | B6: =IF(E6="","",E6-F6) | C6: =IF(B6="","",MAX($B$4:B6)) | D6: =IF(OR(B6="",C6=0),"",B6/C6-1) | E6: 101639.24 | F6: =IFERROR(VLOOKUP(A6, HK_IPO!A:C, 3, TRUE), 0)
A7: 46041 | B7: =IF(E7="","",E7-F7) | C7: =IF(B7="","",MAX($B$4:B7)) | D7: =IF(OR(B7="",C7=0),"",B7/C7-1) | E7: 101720.03 | F7: =IFERROR(VLOOKUP(A7, HK_IPO!A:C, 3, TRUE), 0)
A8: 46042 | B8: =IF(E8="","",E8-F8) | C8: =IF(B8="","",MAX($B$4:B8)) | D8: =IF(OR(B8="",C8=0),"",B8/C8-1) | E8: 101528.06 | F8: =IFERROR(VLOOKUP(A8, HK_IPO!A:C, 3, TRUE), 0)
A9: 46043 | B9: =IF(E9="","",E9-F9) | C9: =IF(B9="","",MAX($B$4:B9)) | D9: =IF(OR(B9="",C9=0),"",B9/C9-1) | E9: 102775.2 | F9: =IFERROR(VLOOKUP(A9, HK_IPO!A:C, 3, TRUE), 0)
A10: 46044 | B10: =IF(E10="","",E10-F10) | C10: =IF(B10="","",MAX($B$4:B10)) | D10: =IF(OR(B10="",C10=0),"",B10/C10-1) | E10: 103332.01 | F10: =IFERROR(VLOOKUP(A10, HK_IPO!A:C, 3, TRUE), 0)
A11: 46045 | B11: =IF(E11="","",E11-F11) | C11: =IF(B11="","",MAX($B$4:B11)) | D11: =IF(OR(B11="",C11=0),"",B11/C11-1) | E11: 103790.64 | F11: =IFERROR(VLOOKUP(A11, HK_IPO!A:C, 3, TRUE), 0)
A12: 46046 | B12: =IF(E12="","",E12-F12) | C12: =IF(B12="","",MAX($B$4:B12)) | D12: =IF(OR(B12="",C12=0),"",B12/C12-1) | E12: 103781.67 | F12: =IFERROR(VLOOKUP(A12, HK_IPO!A:C, 3, TRUE), 0)
A13: 46047 | B13: =IF(E13="","",E13-F13) | C13: =IF(B13="","",MAX($B$4:B13)) | D13: =IF(OR(B13="",C13=0),"",B13/C13-1) | E13: 103777.53 | F13: =IFERROR(VLOOKUP(A13, HK_IPO!A:C, 3, TRUE), 0)
A14: 46048 | B14: =IF(E14="","",E14-F14) | C14: =IF(B14="","",MAX($B$4:B14)) | D14: =IF(OR(B14="",C14=0),"",B14/C14-1) | E14: 103689.02 | F14: =IFERROR(VLOOKUP(A14, HK_IPO!A:C, 3, TRUE), 0)
A15: 46049 | B15: =IF(E15="","",E15-F15) | C15: =IF(B15="","",MAX($B$4:B15)) | D15: =IF(OR(B15="",C15=0),"",B15/C15-1) | E15: 106441.34 | F15: =IFERROR(VLOOKUP(A15, HK_IPO!A:C, 3, TRUE), 0)
... A155: 46189 | B155: =IF(E155="","",E155-F155) | C155: =IF(B155="","",MAX($B$4:B155)) | D155: =IF(OR(B155="",C155=0),"",B155/C155-1) | E155: 130888.19 | F155: =IFERROR(VLOOKUP(A155, HK_IPO!A:C, 3, TRUE), 0)
A156: 46190 | B156: =IF(E156="","",E156-F156) | C156: =IF(B156="","",MAX($B$4:B156)) | D156: =IF(OR(B156="",C156=0),"",B156/C156-1) | F156: =IFERROR(VLOOKUP(A156, HK_IPO!A:C, 3, TRUE), 0)
A157: 46191 | B157: =IF(E157="","",E157-F157) | C157: =IF(B157="","",MAX($B$4:B157)) | D157: =IF(OR(B157="",C157=0),"",B157/C157-1) | F157: =IFERROR(VLOOKUP(A157, HK_IPO!A:C, 3, TRUE), 0)
A158: 46192 | B158: =IF(E158="","",E158-F158) | C158: =IF(B158="","",MAX($B$4:B158)) | D158: =IF(OR(B158="",C158=0),"",B158/C158-1) | F158: =IFERROR(VLOOKUP(A158, HK_IPO!A:C, 3, TRUE), 0)
A159: 46193 | B159: =IF(E159="","",E159-F159) | C159: =IF(B159="","",MAX($B$4:B159)) | D159: =IF(OR(B159="",C159=0),"",B159/C159-1) | F159: =IFERROR(VLOOKUP(A159, HK_IPO!A:C, 3, TRUE), 0)
A160: 46194 | B160: =IF(E160="","",E160-F160) | C160: =IF(B160="","",MAX($B$4:B160)) | D160: =IF(OR(B160="",C160=0),"",B160/C160-1) | F160: =IFERROR(VLOOKUP(A160, HK_IPO!A:C, 3, TRUE), 0)
A161: 46195 | B161: =IF(E161="","",E161-F161) | C161: =IF(B161="","",MAX($B$4:B161)) | D161: =IF(OR(B161="",C161=0),"",B161/C161-1) | F161: =IFERROR(VLOOKUP(A161, HK_IPO!A:C, 3, TRUE), 0)
A162: 46196 | B162: =IF(E162="","",E162-F162) | C162: =IF(B162="","",MAX($B$4:B162)) | D162: =IF(OR(B162="",C162=0),"",B162/C162-1) | F162: =IFERROR(VLOOKUP(A162, HK_IPO!A:C, 3, TRUE), 0)
A163: 46197 | B163: =IF(E163="","",E163-F163) | C163: =IF(B163="","",MAX($B$4:B163)) | D163: =IF(OR(B163="",C163=0),"",B163/C163-1) | F163: =IFERROR(VLOOKUP(A163, HK_IPO!A:C, 3, TRUE), 0)
A164: 46198 | B164: =IF(E164="","",E164-F164) | C164: =IF(B164="","",MAX($B$4:B164)) | D164: =IF(OR(B164="",C164=0),"",B164/C164-1) | F164: =IFERROR(VLOOKUP(A164, HK_IPO!A:C, 3, TRUE), 0)
A165: 46199 | B165: =IF(E165="","",E165-F165) | C165: =IF(B165="","",MAX($B$4:B165)) | D165: =IF(OR(B165="",C165=0),"",B165/C165-1) | F165: =IFERROR(VLOOKUP(A165, HK_IPO!A:C, 3, TRUE), 0)
A166: 46200 | B166: =IF(E166="","",E166-F166) | C166: =IF(B166="","",MAX($B$4:B166)) | D166: =IF(OR(B166="",C166=0),"",B166/C166-1) | F166: =IFERROR(VLOOKUP(A166, HK_IPO!A:C, 3, TRUE), 0)
A167: 46201 | B167: =IF(E167="","",E167-F167) | C167: =IF(B167="","",MAX($B$4:B167)) | D167: =IF(OR(B167="",C167=0),"",B167/C167-1) | F167: =IFERROR(VLOOKUP(A167, HK_IPO!A:C, 3, TRUE), 0)
... A203: 46237 | B203: =IF(E203="","",E203-F203) | C203: =IF(B203="","",MAX($B$4:B203)) | D203: =IF(OR(B203="",C203=0),"",B203/C203-1) | F203: =IFERROR(VLOOKUP(A203, HK_IPO!A:C, 3, TRUE), 0)

Sheet Dashboard
A1: Strategy Dashboard
A3: Metric | B3: Value | D3: Allocation | E3: Weight
A4: Starting Equity | B4: =Config!$B$4 | D4: L0+ | E4: =SUMIF(Holdings!$A$4:$A$11,"L0+",Holdings!$G$4:$G$11)/Holdings!$B$16
A5: Net Deposits | B5: =SUMIFS(Cash_Flow!$C:$C,Cash_Flow!$B:$B,"Deposit")-SUMIFS(Cash_Flow!$C:$C,Cash_Flow!$B:$B,"Withdrawal") | D5: L1 | E5: =SUMIF(Holdings!$A$4:$A$11,"L1",Holdings!$G$4:$G$11)/Holdings!$B$16
A6: Realized PnL | B6: =SUM(Transactions!$N$4:$N$206) | D6: L2 | E6: =SUMIF(Holdings!$A$4:$A$11,"L2",Holdings!$G$4:$G$11)/Holdings!$B$16
A7: Unrealized PnL | B7: =SUM(Holdings!$H$4:$H$11) | D7: Cash | E7: =Holdings!$B$15/Holdings!$B$16
A8: Strategy PnL | B8: =B6+B7
A9: Current Equity | B9: =Holdings!$B$16
A10: Strategy Return | B10: =IF(B4=0,0,B8/B4)
A11: Account Return | B11: =IF(B4+B5=0,0,(B9-B4-B5)/(B4+B5))
A12: Closed Trades | B12: =COUNTIF(Transactions!$N$4:$N$206,">0")+COUNTIF(Transactions!$N$4:$N$206,"<0")
A13: Win Rate | B13: =IF(B12=0,0,COUNTIF(Transactions!$N$4:$N$206,">0")/B12)
A14: Profit Factor | B14: =IF(ABS(SUMIF(Transactions!$N$4:$N$206,"<0"))=0,0,SUMIF(Transactions!$N$4:$N$206,">0")/ABS(SUMIF(Transactions!$N$4:$N$206,"<0")))
A15: Max Drawdown | B15: =MIN(Daily_Equity!$D$4:$D$203)

Sheet HK_IPO
A1: HK IPO Realized PnL Tracker / 港股打新已实现盈亏
A3: Date / 结算日期 | B3: Monthly PnL / 当月盈亏 ($) | C3: Accumulated PnL / 累计盈亏 ($)
A4: 46037 | B4: 0 | C4: =B4
A5: 46053 | B5: 0 | C5: =C4+B5
A6: 46081 | B6: 0 | C6: =C5+B6
A7: 46112 | B7: 0 | C7: =C6+B7
A8: 46142 | B8: 0 | C8: =C7+B8
A9: 46173 | B9: 0 | C9: =C8+B9
A10: 46203 | B10: 0 | C10: =C9+B10
A11: 46234 | B11: 0 | C11: =C10+B11
A12: 46265 | B12: 0 | C12: =C11+B12
